Workbook

Sheet 요약
A1: original 데이터셋 메타데이터 요약
A2: 원본 경로: E:\AI_CCTV_DATASET\original | 파일을 복사하지 않고 현재 폴더를 직접 집계한 결과
A4: 데이터셋 | B4: 작업 | C4: 구조/출처 | D4: 세부 행 | E4: 결함 코드 수 | F4: 이미지 수 | G4: 라벨 수 | H4: 분할 내 매칭 | I4: 실제 미발견 | J4: 상태
A5: rename_data_s20_s22_bbox | B5: BBOX | C5: 서울시 2020·2022 / 결함별 images·labels | D5: 35 | E5: 24 | F5: =SUMIF('상세 현황'!$A$5:$A$97,A5,'상세 현황'!$H$5:$H$97) -> 44474 | G5: =SUMIF('상세 현황'!$A$5:$A$97,A5,'상세 현황'!$I$5:$I$97) -> 44474 | H5: =SUMIF('상세 현황'!$A$5:$A$97,A5,'상세 현황'!$J$5:$J$97) -> 44474 | I5: =SUMIF('상세 현황'!$A$5:$A$97,A5,'상세 현황'!$N$5:$N$97)+SUMIF('상세 현황'!$A$5:$A$97,A5,'상세 현황'!$O$5:$O$97) -> 0 | J5: =IF(I5=0,"일치","확인 필요") -> 일치
A6: aihub_data_bbox | B6: BBOX | C6: AI Hub / image·labels 통합 | D6: 14 | E6: 14 | F6: =SUMIF('상세 현황'!$A$5:$A$97,A6,'상세 현황'!$H$5:$H$97) -> 423000 | G6: =SUMIF('상세 현황'!$A$5:$A$97,A6,'상세 현황'!$I$5:$I$97) -> 423000 | H6: =SUMIF('상세 현황'!$A$5:$A$97,A6,'상세 현황'!$J$5:$J$97) -> 423000 | I6: =SUMIF('상세 현황'!$A$5:$A$97,A6,'상세 현황'!$N$5:$N$97)+SUMIF('상세 현황'!$A$5:$A$97,A6,'상세 현황'!$O$5:$O$97) -> 0 | J6: =IF(I6=0,"일치","확인 필요") -> 일치
A7: rename_data_s20_s22_seg | B7: SEG | C7: 서울시 2020·2022 / 결함별 images·labels | D7: 35 | E7: 24 | F7: =SUMIF('상세 현황'!$A$5:$A$97,A7,'상세 현황'!$H$5:$H$97) -> 11040 | G7: =SUMIF('상세 현황'!$A$5:$A$97,A7,'상세 현황'!$I$5:$I$97) -> 11040 | H7: =SUMIF('상세 현황'!$A$5:$A$97,A7,'상세 현황'!$J$5:$J$97) -> 11040 | I7: =SUMIF('상세 현황'!$A$5:$A$97,A7,'상세 현황'!$N$5:$N$97)+SUMIF('상세 현황'!$A$5:$A$97,A7,'상세 현황'!$O$5:$O$97) -> 0 | J7: =IF(I7=0,"일치","확인 필요") -> 일치
A8: aihub_data_seg | B8: SEG | C8: AI Hub / image·labels 분리 | D8: 9 | E8: 9 | F8: =SUMIF('상세 현황'!$A$5:$A$97,A8,'상세 현황'!$H$5:$H$97) -> 29973 | G8: =SUMIF('상세 현황'!$A$5:$A$97,A8,'상세 현황'!$I$5:$I$97) -> 29973 | H8: =SUMIF('상세 현황'!$A$5:$A$97,A8,'상세 현황'!$J$5:$J$97) -> 29973 | I8: =SUMIF('상세 현황'!$A$5:$A$97,A8,'상세 현황'!$N$5:$N$97)+SUMIF('상세 현황'!$A$5:$A$97,A8,'상세 현황'!$O$5:$O$97) -> 0 | J8: =IF(I8=0,"일치","확인 필요") -> 일치
A9: 전체 합계 | F9: =SUM(F5:F8) -> 508487 | G9: =SUM(G5:G8) -> 508487 | H9: =SUM(H5:H8) -> 508487 | I9: =SUM(I5:I8) -> 0 | J9: =IF(I9=0,"일치","확인 필요") -> 일치
A11: 2026-07-14 AI Hub BBox 통합 및 중복 정리 내역
A12: Train·Vaild를 image/labels 구조로 통합 완료 → 이미지 423,000장 / 라벨 423,000개 / 파일명 1:1 일치
A13: 중복 라벨 5,000개 제거. CL은 전역 클래스 번호 1인 라벨 유지. 기존 Train_* 및 Vaild_* 폴더 삭제 완료.
A15: 실제로 아직 찾지 못한 항목 (전체 데이터셋 기준)
A16: 데이터셋 | B16: 작업 | C16: 구분 | D16: 코드 | E16: 결함 종류 | F16: 이미지만 | G16: 라벨만 | H16: 메모
A17: 2026-07-16 정리 완료: aihub_data_seg 라벨 없는 이미지 26개(BK2·CC7·CL5·DS1·ETC6·JF3·LP1·SD1) 삭제, 전부 원본 AI Hub 라벨과 일치 확인됨

Sheet 결함별 합계
A1: 결함별 보유 수량 합계
A2: 이미지 수를 학습 샘플 수로 보고, BBOX와 SEG를 분리하여 합산했습니다.
A4: 작업 | B4: 코드 | C4: 결함 종류 | D4: 이미지 수 | E4: 라벨 수 | F4: 분할 내 매칭 | G4: 실제 이미지만 | H4: 실제 라벨만 | I4: 원본 묶음 수 | J4: 상태
A5: BBOX | B5: BC | C5: 좌굴 | D5: =SUMIFS('상세 현황'!$H$5:$H$97,'상세 현황'!$B$5:$B$97,A5,'상세 현황'!$E$5:$E$97,B5) -> 420 | E5: =SUMIFS('상세 현황'!$I$5:$I$97,'상세 현황'!$B$5:$B$97,A5,'상세 현황'!$E$5:$E$97,B5) -> 420 | F5: =SUMIFS('상세 현황'!$J$5:$J$97,'상세 현황'!$B$5:$B$97,A5,'상세 현황'!$E$5:$E$97,B5) -> 420 | G5: =SUMIFS('상세 현황'!$N$5:$N$97,'상세 현황'!$B$5:$B$97,A5,'상세 현황'!$E$5:$E$97,B5) -> 0 | H5: =SUMIFS('상세 현황'!$O$5:$O$97,'상세 현황'!$B$5:$B$97,A5,'상세 현황'!$E$5:$E$97,B5) -> 0 | I5: 1 | J5: =IF(G5+H5=0,"일치","확인 필요") -> 일치
A6: BBOX | B6: BK | C6: 파손 | D6: =SUMIFS('상세 현황'!$H$5:$H$97,'상세 현황'!$B$5:$B$97,A6,'상세 현황'!$E$5:$E$97,B6) -> 38115 | E6: =SUMIFS('상세 현황'!$I$5:$I$97,'상세 현황'!$B$5:$B$97,A6,'상세 현황'!$E$5:$E$97,B6) -> 38115 | F6: =SUMIFS('상세 현황'!$J$5:$J$97,'상세 현황'!$B$5:$B$97,A6,'상세 현황'!$E$5:$E$97,B6) -> 38115 | G6: =SUMIFS('상세 현황'!$N$5:$N$97,'상세 현황'!$B$5:$B$97,A6,'상세 현황'!$E$5:$E$97,B6) -> 0 | H6: =SUMIFS('상세 현황'!$O$5:$O$97,'상세 현황'!$B$5:$B$97,A6,'상세 현황'!$E$5:$E$97,B6) -> 0 | I6: 2 | J6: =IF(G6+H6=0,"일치","확인 필요") -> 일치
A7: BBOX | B7: CC | C7: 균열(원주) | D7: =SUMIFS('상세 현황'!$H$5:$H$97,'상세 현황'!$B$5:$B$97,A7,'상세 현황'!$E$5:$E$97,B7) -> 19994 | E7: =SUMIFS('상세 현황'!$I$5:$I$97,'상세 현황'!$B$5:$B$97,A7,'상세 현황'!$E$5:$E$97,B7) -> 19994 | F7: =SUMIFS('상세 현황'!$J$5:$J$97,'상세 현황'!$B$5:$B$97,A7,'상세 현황'!$E$5:$E$97,B7) -> 19994 | G7: =SUMIFS('상세 현황'!$N$5:$N$97,'상세 현황'!$B$5:$B$97,A7,'상세 현황'!$E$5:$E$97,B7) -> 0 | H7: =SUMIFS('상세 현황'!$O$5:$O$97,'상세 현황'!$B$5:$B$97,A7,'상세 현황'!$E$5:$E$97,B7) -> 0 | I7: 2 | J7: =IF(G7+H7=0,"일치","확인 필요") -> 일치
A8: BBOX | B8: CL | C8: 균열(길이) | D8: =SUMIFS('상세 현황'!$H$5:$H$97,'상세 현황'!$B$5:$B$97,A8,'상세 현황'!$E$5:$E$97,B8) -> 19859 | E8: =SUMIFS('상세 현황'!$I$5:$I$97,'상세 현황'!$B$5:$B$97,A8,'상세 현황'!$E$5:$E$97,B8) -> 19859 | F8: =SUMIFS('상세 현황'!$J$5:$J$97,'상세 현황'!$B$5:$B$97,A8,'상세 현황'!$E$5:$E$97,B8) -> 19859 | G8: =SUMIFS('상세 현황'!$N$5:$N$97,'상세 현황'!$B$5:$B$97,A8,'상세 현황'!$E$5:$E$97,B8) -> 0 | H8: =SUMIFS('상세 현황'!$O$5:$O$97,'상세 현황'!$B$5:$B$97,A8,'상세 현황'!$E$5:$E$97,B8) -> 0 | I8: 2 | J8: =IF(G8+H8=0,"일치","확인 필요") -> 일치
A9: BBOX | B9: CM | C9: 균열(복합) | D9: =SUMIFS('상세 현황'!$H$5:$H$97,'상세 현황'!$B$5:$B$97,A9,'상세 현황'!$E$5:$E$97,B9) -> 771 | E9: =SUMIFS('상세 현황'!$I$5:$I$97,'상세 현황'!$B$5:$B$97,A9,'상세 현황'!$E$5:$E$97,B9) -> 771 | F9: =SUMIFS('상세 현황'!$J$5:$J$97,'상세 현황'!$B$5:$B$97,A9,'상세 현황'!$E$5:$E$97,B9) -> 771 | G9: =SUMIFS('상세 현황'!$N$5:$N$97,'상세 현황'!$B$5:$B$97,A9,'상세 현황'!$E$5:$E$97,B9) -> 0 | H9: =SUMIFS('상세 현황'!$O$5:$O$97,'상세 현황'!$B$5:$B$97,A9,'상세 현황'!$E$5:$E$97,B9) -> 0 | I9: 1 | J9: =IF(G9+H9=0,"일치","확인 필요") -> 일치
A10: BBOX | B10: CX | C10: 붕괴 | D10: =SUMIFS('상세 현황'!$H$5:$H$97,'상세 현황'!$B$5:$B$97,A10,'상세 현황'!$E$5:$E$97,B10) -> 14 | E10: =SUMIFS('상세 현황'!$I$5:$I$97,'상세 현황'!$B$5:$B$97,A10,'상세 현황'!$E$5:$E$97,B10) -> 14 | F10: =SUMIFS('상세 현황'!$J$5:$J$97,'상세 현황'!$B$5:$B$97,A10,'상세 현황'!$E$5:$E$97,B10) -> 14 | G10: =SUMIFS('상세 현황'!$N$5:$N$97,'상세 현황'!$B$5:$B$97,A10,'상세 현황'!$E$5:$E$97,B10) -> 0 | H10: =SUMIFS('상세 현황'!$O$5:$O$97,'상세 현황'!$B$5:$B$97,A10,'상세 현황'!$E$5:$E$97,B10) -> 0 | I10: 1 | J10: =IF(G10+H10=0,"일치","확인 필요") -> 일치
A11: BBOX | B11: DE | C11: 내피생성 | D11: =SUMIFS('상세 현황'!$H$5:$H$97,'상세 현황'!$B$5:$B$97,A11,'상세 현황'!$E$5:$E$97,B11) -> 34 | E11: =SUMIFS('상세 현황'!$I$5:$I$97,'상세 현황'!$B$5:$B$97,A11,'상세 현황'!$E$5:$E$97,B11) -> 34 | F11: =SUMIFS('상세 현황'!$J$5:$J$97,'상세 현황'!$B$5:$B$97,A11,'상세 현황'!$E$5:$E$97,B11) -> 34 | G11: =SUMIFS('상세 현황'!$N$5:$N$97,'상세 현황'!$B$5:$B$97,A11,'상세 현황'!$E$5:$E$97,B11) -> 0 | H11: =SUMIFS('상세 현황'!$O$5:$O$97,'상세 현황'!$B$5:$B$97,A11,'상세 현황'!$E$5:$E$97,B11) -> 0 | I11: 1 | J11: =IF(G11+H11=0,"일치","확인 필요") -> 일치
A12: BBOX | B12: DF | C12: 변형 | D12: =SUMIFS('상세 현황'!$H$5:$H$97,'상세 현황'!$B$5:$B$97,A12,'상세 현황'!$E$5:$E$97,B12) -> 285 | E12: =SUMIFS('상세 현황'!$I$5:$I$97,'상세 현황'!$B$5:$B$97,A12,'상세 현황'!$E$5:$E$97,B12) -> 285 | F12: =SUMIFS('상세 현황'!$J$5:$J$97,'상세 현황'!$B$5:$B$97,A12,'상세 현황'!$E$5:$E$97,B12) -> 285 | G12: =SUMIFS('상세 현황'!$N$5:$N$97,'상세 현황'!$B$5:$B$97,A12,'상세 현황'!$E$5:$E$97,B12) -> 0 | H12: =SUMIFS('상세 현황'!$O$5:$O$97,'상세 현황'!$B$5:$B$97,A12,'상세 현황'!$E$5:$E$97,B12) -> 0 | I12: 1 | J12: =IF(G12+H12=0,"일치","확인 필요") -> 일치
A13: BBOX | B13: DG | C13: 폐유부착 | D13: =SUMIFS('상세 현황'!$H$5:$H$97,'상세 현황'!$B$5:$B$97,A13,'상세 현황'!$E$5:$E$97,B13) -> 303 | E13: =SUMIFS('상세 현황'!$I$5:$I$97,'상세 현황'!$B$5:$B$97,A13,'상세 현황'!$E$5:$E$97,B13) -> 303 | F13: =SUMIFS('상세 현황'!$J$5:$J$97,'상세 현황'!$B$5:$B$97,A13,'상세 현황'!$E$5:$E$97,B13) -> 303 | G13: =SUMIFS('상세 현황'!$N$5:$N$97,'상세 현황'!$B$5:$B$97,A13,'상세 현황'!$E$5:$E$97,B13) -> 0 | H13: =SUMIFS('상세 현황'!$O$5:$O$97,'상세 현황'!$B$5:$B$97,A13,'상세 현황'!$E$5:$E$97,B13) -> 0 | I13: 1 | J13: =IF(G13+H13=0,"일치","확인 필요") -> 일치
A14: BBOX | B14: DS | C14: 토사퇴적 | D14: =SUMIFS('상세 현황'!$H$5:$H$97,'상세 현황'!$B$5:$B$97,A14,'상세 현황'!$E$5:$E$97,B14) -> 29992 | E14: =SUMIFS('상세 현황'!$I$5:$I$97,'상세 현황'!$B$5:$B$97,A14,'상세 현황'!$E$5:$E$97,B14) -> 29992 | F14: =SUMIFS('상세 현황'!$J$5:$J$97,'상세 현황'!$B$5:$B$97,A14,'상세 현황'!$E$5:$E$97,B14) -> 29992 | G14: =SUMIFS('상세 현황'!$N$5:$N$97,'상세 현황'!$B$5:$B$97,A14,'상세 현황'!$E$5:$E$97,B14) -> 0 | H14: =SUMIFS('상세 현황'!$O$5:$O$97,'상세 현황'!$B$5:$B$97,A14,'상세 현황'!$E$5:$E$97,B14) -> 0 | I14: 2 | J14: =IF(G14+H14=0,"일치","확인 필요") -> 일치
A15: BBOX | B15: ETC | C15: 기타 | D15: =SUMIFS('상세 현황'!$H$5:$H$97,'상세 현황'!$B$5:$B$97,A15,'상세 현황'!$E$5:$E$97,B15) -> 36000 | E15: =SUMIFS('상세 현황'!$I$5:$I$97,'상세 현황'!$B$5:$B$97,A15,'상세 현황'!$E$5:$E$97,B15) -> 36000 | F15: =SUMIFS('상세 현황'!$J$5:$J$97,'상세 현황'!$B$5:$B$97,A15,'상세 현황'!$E$5:$E$97,B15) -> 36000 | G15: =SUMIFS('상세 현황'!$N$5:$N$97,'상세 현황'!$B$5:$B$97,A15,'상세 현황'!$E$5:$E$97,B15) -> 0 | H15: =SUMIFS('상세 현황'!$O$5:$O$97,'상세 현황'!$B$5:$B$97,A15,'상세 현황'!$E$5:$E$97,B15) -> 0 | I15: 1 | J15: =IF(G15+H15=0,"일치","확인 필요") -> 일치
A16: BBOX | B16: HL | C16: 천공 | D16: =SUMIFS('상세 현황'!$H$5:$H$97,'상세 현황'!$B$5:$B$97,A16,'상세 현황'!$E$5:$E$97,B16) -> 1107 | E16: =SUMIFS('상세 현황'!$I$5:$I$97,'상세 현황'!$B$5:$B$97,A16,'상세 현황'!$E$5:$E$97,B16) -> 1107 | F16: =SUMIFS('상세 현황'!$J$5:$J$97,'상세 현황'!$B$5:$B$97,A16,'상세 현황'!$E$5:$E$97,B16) -> 1107 | G16: =SUMIFS('상세 현황'!$N$5:$N$97,'상세 현황'!$B$5:$B$97,A16,'상세 현황'!$E$5:$E$97,B16) -> 0 | H16: =SUMIFS('상세 현황'!$O$5:$O$97,'상세 현황'!$B$5:$B$97,A16,'상세 현황'!$E$5:$E$97,B16) -> 0 | I16: 1 | J16: =IF(G16+H16=0,"일치","확인 필요") -> 일치
... A59: SEG | B59: TO | C59: 임시장애물 | D59: =SUMIFS('상세 현황'!$H$5:$H$97,'상세 현황'!$B$5:$B$97,A59,'상세 현황'!$E$5:$E$97,B59) -> 181 | E59: =SUMIFS('상세 현황'!$I$5:$I$97,'상세 현황'!$B$5:$B$97,A59,'상세 현황'!$E$5:$E$97,B59) -> 181 | F59: =SUMIFS('상세 현황'!$J$5:$J$97,'상세 현황'!$B$5:$B$97,A59,'상세 현황'!$E$5:$E$97,B59) -> 181 | G59: =SUMIFS('상세 현황'!$N$5:$N$97,'상세 현황'!$B$5:$B$97,A59,'상세 현황'!$E$5:$E$97,B59) -> 0 | H59: =SUMIFS('상세 현황'!$O$5:$O$97,'상세 현황'!$B$5:$B$97,A59,'상세 현황'!$E$5:$E$97,B59) -> 0 | I59: 1 | J59: =IF(G59+H59=0,"일치","확인 필요") -> 일치

Sheet 상세 현황
A1: AI_CCTV_DATASET / original 상세 현황
A2: 기준 경로: E:\AI_CCTV_DATASET\original | 집계 시각: 2026. 7. 14. AM 3:13:11 (KST)
A4: 데이터셋 | B4: 작업 | C4: 구분 | D4: 연도 | E4: 코드 | F4: 결함 종류 | G4: 원본 폴더명 | H4: 이미지 수 | I4: 라벨 수 | J4: 분할 내 매칭 | K4: 분할 내 이미지만 | L4: 분할 내 라벨만 | M4: 다른 split에서 찾음 | N4: 실제 이미지만 | O4: 실제 라벨만 | P4: 최종 상태 | Q4: 확인/조치 내용 | R4: 이미지 형식 | S4: 라벨 형식 | T4: 이미지 원본 위치 | U4: 라벨 원본 위치
A5: aihub_data_bbox | B5: BBOX | C5: 통합 | E5: BK | F5: 파손 | G5: BK | H5: 36000 | I5: 36000 | J5: 36000 | K5: 0 | L5: 0 | M5: 0 | N5: 0 | O5: 0 | P5: 일치 | R5: .png:36000 | S5: .txt:36000 | T5: E:\AI_CCTV_DATASET\original\aihub_data_bbox\image\BK | U5: E:\AI_CCTV_DATASET\original\aihub_data_bbox\labels\BK
A6: aihub_data_bbox | B6: BBOX | C6: 통합 | E6: CC | F6: 균열(원주) | G6: CC | H6: 18000 | I6: 18000 | J6: 18000 | K6: 0 | L6: 0 | M6: 0 | N6: 0 | O6: 0 | P6: 일치 | R6: .png:18000 | S6: .txt:18000 | T6: E:\AI_CCTV_DATASET\original\aihub_data_bbox\image\CC | U6: E:\AI_CCTV_DATASET\original\aihub_data_bbox\labels\CC
A7: aihub_data_bbox | B7: BBOX | C7: 통합 | E7: CL | F7: 균열(길이) | G7: CL | H7: 18000 | I7: 18000 | J7: 18000 | K7: 0 | L7: 0 | M7: 0 | N7: 0 | O7: 0 | P7: 일치 | R7: .png:18000 | S7: .txt:18000 | T7: E:\AI_CCTV_DATASET\original\aihub_data_bbox\image\CL | U7: E:\AI_CCTV_DATASET\original\aihub_data_bbox\labels\CL
A8: aihub_data_bbox | B8: BBOX | C8: 통합 | E8: DS | F8: 토사퇴적 | G8: DS | H8: 27000 | I8: 27000 | J8: 27000 | K8: 0 | L8: 0 | M8: 0 | N8: 0 | O8: 0 | P8: 일치 | R8: .png:27000 | S8: .txt:27000 | T8: E:\AI_CCTV_DATASET\original\aihub_data_bbox\image\DS | U8: E:\AI_CCTV_DATASET\original\aihub_data_bbox\labels\DS
A9: aihub_data_bbox | B9: BBOX | C9: 통합 | E9: ETC | F9: 기타 | G9: ETC | H9: 36000 | I9: 36000 | J9: 36000 | K9: 0 | L9: 0 | M9: 0 | N9: 0 | O9: 0 | P9: 일치 | R9: .png:36000 | S9: .txt:36000 | T9: E:\AI_CCTV_DATASET\original\aihub_data_bbox\image\ETC | U9: E:\AI_CCTV_DATASET\original\aihub_data_bbox\labels\ETC
A10: aihub_data_bbox | B10: BBOX | C10: 통합 | E10: IN | F10: 하수관로 내부 | G10: IN | H10: 90000 | I10: 90000 | J10: 90000 | K10: 0 | L10: 0 | M10: 0 | N10: 0 | O10: 0 | P10: 일치 | R10: .png:90000 | S10: .txt:90000 | T10: E:\AI_CCTV_DATASET\original\aihub_data_bbox\image\IN | U10: E:\AI_CCTV_DATASET\original\aihub_data_bbox\labels\IN
A11: aihub_data_bbox | B11: BBOX | C11: 통합 | E11: JD | F11: 이음부(단차) | G11: JD | H11: 36000 | I11: 36000 | J11: 36000 | K11: 0 | L11: 0 | M11: 0 | N11: 0 | O11: 0 | P11: 일치 | R11: .png:36000 | S11: .txt:36000 | T11: E:\AI_CCTV_DATASET\original\aihub_data_bbox\image\JD | U11: E:\AI_CCTV_DATASET\original\aihub_data_bbox\labels\JD
A12: aihub_data_bbox | B12: BBOX | C12: 통합 | E12: JF | F12: 이음부(손상) | G12: JF | H12: 36000 | I12: 36000 | J12: 36000 | K12: 0 | L12: 0 | M12: 0 | N12: 0 | O12: 0 | P12: 일치 | R12: .png:36000 | S12: .txt:36000 | T12: E:\AI_CCTV_DATASET\original\aihub_data_bbox\image\JF | U12: E:\AI_CCTV_DATASET\original\aihub_data_bbox\labels\JF
A13: aihub_data_bbox | B13: BBOX | C13: 통합 | E13: LP | F13: 연결관(돌출) | G13: LP | H13: 36000 | I13: 36000 | J13: 36000 | K13: 0 | L13: 0 | M13: 0 | N13: 0 | O13: 0 | P13: 일치 | R13: .png:36000 | S13: .txt:36000 | T13: E:\AI_CCTV_DATASET\original\aihub_data_bbox\image\LP | U13: E:\AI_CCTV_DATASET\original\aihub_data_bbox\labels\LP
A14: aihub_data_bbox | B14: BBOX | C14: 통합 | E14: OUT_CAR | F14: 하수관로 외부(자동차) | G14: OUT_CAR | H14: 9000 | I14: 9000 | J14: 9000 | K14: 0 | L14: 0 | M14: 0 | N14: 0 | O14: 0 | P14: 일치 | R14: .png:9000 | S14: .txt:9000 | T14: E:\AI_CCTV_DATASET\original\aihub_data_bbox\image\OUT_CAR | U14: E:\AI_CCTV_DATASET\original\aihub_data_bbox\labels\OUT_CAR
A15: aihub_data_bbox | B15: BBOX | C15: 통합 | E15: OUT_INVERT | F15: 하수관로 외부(인버트) | G15: OUT_INVERT | H15: 9000 | I15: 9000 | J15: 9000 | K15: 0 | L15: 0 | M15: 0 | N15: 0 | O15: 0 | P15: 일치 | R15: .png:9000 | S15: .txt:9000 | T15: E:\AI_CCTV_DATASET\original\aihub_data_bbox\image\OUT_INVERT | U15: E:\AI_CCTV_DATASET\original\aihub_data_bbox\labels\OUT_INVERT
A16: aihub_data_bbox | B16: BBOX | C16: 통합 | E16: OUT_MH | F16: 하수관로 외부(맨홀) | G16: OUT_MH | H16: 9000 | I16: 9000 | J16: 9000 | K16: 0 | L16: 0 | M16: 0 | N16: 0 | O16: 0 | P16: 일치 | R16: .png:9000 | S16: .txt:9000 | T16: E:\AI_CCTV_DATASET\original\aihub_data_bbox\image\OUT_MH | U16: E:\AI_CCTV_DATASET\original\aihub_data_bbox\labels\OUT_MH
... A18: aihub_data_bbox | B18: BBOX | C18: 통합 | E18: SD | F18: 표면손상 | G18: SD | H18: 18000 | I18: 18000 | J18: 18000 | K18: 0 | L18: 0 | M18: 0 | N18: 0 | O18: 0 | P18: 일치 | R18: .png:18000 | S18: .txt:18000 | T18: E:\AI_CCTV_DATASET\original\aihub_data_bbox\image\SD | U18: E:\AI_CCTV_DATASET\original\aihub_data_bbox\labels\SD
A19: rename_data_s20_s22_bbox | B19: BBOX | C19: S20 | D19: 2020 | E19: BC | F19: 좌굴 | G19: BC_S20_좌굴 | H19: 420 | I19: 420 | J19: 420 | K19: 0 | L19: 0 | M19: 0 | N19: 0 | O19: 0 | P19: 일치 | R19: .jpg:402, .png:18 | S19: .xml:420 | T19: E:\AI_CCTV_DATASET\original\rename_data_s20_s22_bbox\BC_S20_좌굴\images | U19: E:\AI_CCTV_DATASET\original\rename_data_s20_s22_bbox\BC_S20_좌굴\labels
A20: rename_data_s20_s22_bbox | B20: BBOX | C20: S20 | D20: 2020 | E20: BK | F20: 파손 | G20: BK_S20_파손 | H20: 1718 | I20: 1718 | J20: 1718 | K20: 0 | L20: 0 | M20: 0 | N20: 0 | O20: 0 | P20: 일치 | R20: .jpg:1084, .png:634 | S20: .txt:1718 | T20: E:\AI_CCTV_DATASET\original\rename_data_s20_s22_bbox\BK_S20_파손\images | U20: E:\AI_CCTV_DATASET\original\rename_data_s20_s22_bbox\BK_S20_파손\labels
A21: rename_data_s20_s22_bbox | B21: BBOX | C21: S22 | D21: 2022 | E21: BK | F21: 파손 | G21: S22_BK_05파손(BK) | H21: 397 | I21: 397 | J21: 397 | K21: 0 | L21: 0 | M21: 0 | N21: 0 | O21: 0 | P21: 일치 | R21: .png:397 | S21: .json:397 | T21: E:\AI_CCTV_DATASET\original\rename_data_s20_s22_bbox\S22_BK_05파손(BK)\images | U21: E:\AI_CCTV_DATASET\original\rename_data_s20_s22_bbox\S22_BK_05파손(BK)\labels
A22: rename_data_s20_s22_bbox | B22: BBOX | C22: S20 | D22: 2020 | E22: CC | F22: 균열(원주) | G22: CC_S20_균열(원주) | H22: 1250 | I22: 1250 | J22: 1250 | K22: 0 | L22: 0 | M22: 0 | N22: 0 | O22: 0 | P22: 일치 | R22: .jpg:1126, .png:124 | S22: .xml:1250 | T22: E:\AI_CCTV_DATASET\original\rename_data_s20_s22_bbox\CC_S20_균열(원주)\images | U22: E:\AI_CCTV_DATASET\original\rename_data_s20_s22_bbox\CC_S20_균열(원주)\labels
A23: rename_data_s20_s22_bbox | B23: BBOX | C23: S22 | D23: 2022 | E23: CC | F23: 균열(원주) | G23: S22_CC_03균열원주(CC) | H23: 744 | I23: 744 | J23: 744 | K23: 0 | L23: 0 | M23: 0 | N23: 0 | O23: 0 | P23: 일치 | R23: .png:744 | S23: .json:744 | T23: E:\AI_CCTV_DATASET\original\rename_data_s20_s22_bbox\S22_CC_03균열원주(CC)\images | U23: E:\AI_CCTV_DATASET\original\rename_data_s20_s22_bbox\S22_CC_03균열원주(CC)\labels
A24: rename_data_s20_s22_bbox | B24: BBOX | C24: S20 | D24: 2020 | E24: CL | F24: 균열(길이) | G24: CL_S20_균열(길이) | H24: 1349 | I24: 1349 | J24: 1349 | K24: 0 | L24: 0 | M24: 0 | N24: 0 | O24: 0 | P24: 일치 | R24: .jpg:1073, .png:276 | S24: .txt:1349 | T24: E:\AI_CCTV_DATASET\original\rename_data_s20_s22_bbox\CL_S20_균열(길이)\images | U24: E:\AI_CCTV_DATASET\original\rename_data_s20_s22_bbox\CL_S20_균열(길이)\labels
A25: rename_data_s20_s22_bbox | B25: BBOX | C25: S22 | D25: 2022 | E25: CL | F25: 균열(길이) | G25: S22_CL_01균열길이(CL) | H25: 510 | I25: 510 | J25: 510 | K25: 0 | L25: 0 | M25: 0 | N25: 0 | O25: 0 | P25: 일치 | R25: .png:510 | S25: .json:510 | T25: E:\AI_CCTV_DATASET\original\rename_data_s20_s22_bbox\S22_CL_01균열길이(CL)\images | U25: E:\AI_CCTV_DATASET\original\rename_data_s20_s22_bbox\S22_CL_01균열길이(CL)\labels
A26: rename_data_s20_s22_bbox | B26: BBOX | C26: S20 | D26: 2020 | E26: CM | F26: 균열(복합) | G26: CM_S20_균열(복합) | H26: 730 | I26: 730 | J26: 730 | K26: 0 | L26: 0 | M26: 0 | N26: 0 | O26: 0 | P26: 일치 | R26: .jpg:389, .png:341 | S26: .xml:730 | T26: E:\AI_CCTV_DATASET\original\rename_data_s20_s22_bbox\CM_S20_균열(복합)\images | U26: E:\AI_CCTV_DATASET\original\rename_data_s20_s22_bbox\CM_S20_균열(복합)\labels
A27: rename_data_s20_s22_bbox | B27: BBOX | C27: S22 | D27: 2022 | E27: CM | F27: 균열(복합) | G27: S22_CM_02균열복합(CM) | H27: 41 | I27: 41 | J27: 41 | K27: 0 | L27: 0 | M27: 0 | N27: 0 | O27: 0 | P27: 일치 | R27: .png:41 | S27: .json:41 | T27: E:\AI_CCTV_DATASET\original\rename_data_s20_s22_bbox\S22_CM_02균열복합(CM)\images | U27: E:\AI_CCTV_DATASET\original\rename_data_s20_s22_bbox\S22_CM_02균열복합(CM)\labels
A28: rename_data_s20_s22_bbox | B28: BBOX | C28: S20 | D28: 2020 | E28: CX | F28: 붕괴 | G28: CX_S20_붕괴 | H28: 14 | I28: 14 | J28: 14 | K28: 0 | L28: 0 | M28: 0 | N28: 0 | O28: 0 | P28: 일치 | R28: .jpg:14 | S28: .xml:14 | T28: E:\AI_CCTV_DATASET\original\rename_data_s20_s22_bbox\CX_S20_붕괴\images | U28: E:\AI_CCTV_DATASET\original\rename_data_s20_s22_bbox\CX_S20_붕괴\labels
A29: rename_data_s20_s22_bbox | B29: BBOX | C29: S20 | D29: 2020 | E29: DE | F29: 내피생성 | G29: DE_S20_내피생성 | H29: 34 | I29: 34 | J29: 34 | K29: 0 | L29: 0 | M29: 0 | N29: 0 | O29: 0 | P29: 일치 | R29: .jpg:19, .png:15 | S29: .xml:34 | T29: E:\AI_CCTV_DATASET\original\rename_data_s20_s22_bbox\DE_S20_내피생성\images | U29: E:\AI_CCTV_DATASET\original\rename_data_s20_s22_bbox\DE_S20_내피생성\labels
A30: rename_data_s20_s22_bbox | B30: BBOX | C30: S20 | D30: 2020 | E30: DF | F30: 변형 | G30: DF_S20_변형(단면형태변화) | H30: 285 | I30: 285 | J30: 285 | K30: 0 | L30: 0 | M30: 0 | N30: 0 | O30: 0 | P30: 일치 | R30: .png:249, .jpg:36 | S30: .txt:285 | T30: E:\AI_CCTV_DATASET\original\rename_data_s20_s22_bbox\DF_S20_변형(단면형태변화)\images | U30: E:\AI_CCTV_DATASET\original\rename_data_s20_s22_bbox\DF_S20_변형(단면형태변화)\labels
... A53: rename_data_s20_s22_bbox | B53: BBOX | C53: S20 | D53: 2020 | E53: TO | F53: 임시장애물 | G53: TO_S20_임시장애물 | H53: 680 | I53: 680 | J53: 680 | K53: 0 | L53: 0 | M53: 0 | N53: 0 | O53: 0 | P53: 일치 | R53: .png:514, .jpg:166 | S53: .xml:680 | T53: E:\AI_CCTV_DATASET\original\rename_data_s20_s22_bbox\TO_S20_임시장애물\images | U53: E:\AI_CCTV_DATASET\original\rename_data_s20_s22_bbox\TO_S20_임시장애물\labels
A54: aihub_data_seg | B54: SEG | C54: 전체 | E54: BK | F54: 파손 | G54: 1-3.파손(Broken-Pipe,BK) | H54: 2998 | I54: 2998 | J54: 2998 | K54: 0 | L54: 0 | M54: 0 | N54: 0 | O54: 0 | P54: 일치 | R54: .png:2998 | S54: .txt:2998 | T54: E:\AI_CCTV_DATASET\original\aihub_data_seg\image\1-3.파손(Broken-Pipe,BK) | U54: E:\AI_CCTV_DATASET\original\aihub_data_seg\labels\BK
A55: aihub_data_seg | B55: SEG | C55: 전체 | E55: CC | F55: 균열(원주) | G55: 1-1-2.균열-원주(Crack-Circumferential,CC) | H55: 2993 | I55: 2993 | J55: 2993 | K55: 0 | L55: 0 | M55: 0 | N55: 0 | O55: 0 | P55: 일치 | R55: .png:2993 | S55: .txt:2993 | T55: E:\AI_CCTV_DATASET\original\aihub_data_seg\image\1-1-2.균열-원주(Crack-Circumferential,CC) | U55: E:\AI_CCTV_DATASET\original\aihub_data_seg\labels\CC
A56: aihub_data_seg | B56: SEG | C56: 전체 | E56: CL | F56: 균열(길이) | G56: 1-1-1.균열-길이(Crack-Longitudinal,CL) | H56: 3995 | I56: 3995 | J56: 3995 | K56: 0 | L56: 0 | M56: 0 | N56: 0 | O56: 0 | P56: 일치 | R56: .png:3995 | S56: .txt:3995 | T56: E:\AI_CCTV_DATASET\original\aihub_data_seg\image\1-1-1.균열-길이(Crack-Longitudinal,CL) | U56: E:\AI_CCTV_DATASET\original\aihub_data_seg\labels\CL
A57: aihub_data_seg | B57: SEG | C57: 전체 | E57: DS | F57: 토사퇴적 | G57: 1-7.토사퇴적(Deposits-Silty,DS) | H57: 2999 | I57: 2999 | J57: 2999 | K57: 0 | L57: 0 | M57: 0 | N57: 0 | O57: 0 | P57: 일치 | R57: .png:2999 | S57: .txt:2999 | T57: E:\AI_CCTV_DATASET\original\aihub_data_seg\image\1-7.토사퇴적(Deposits-Silty,DS) | U57: E:\AI_CCTV_DATASET\original\aihub_data_seg\labels\DS
A58: aihub_data_seg | B58: SEG | C58: 전체 | E58: ETC | F58: 기타 | G58: 1-8.기타결함(Etc.,ETC) | H58: 4994 | I58: 4994 | J58: 4994 | K58: 0 | L58: 0 | M58: 0 | N58: 0 | O58: 0 | P58: 일치 | R58: .png:4994 | S58: .txt:4994 | T58: E:\AI_CCTV_DATASET\original\aihub_data_seg\image\1-8.기타결함(Etc.,ETC) | U58: E:\AI_CCTV_DATASET\original\aihub_data_seg\labels\ETC
A59: aihub_data_seg | B59: SEG | C59: 전체 | E59: JD | F59: 이음부(단차) | G59: 1-6.이음부-단차(Joint-Displaced,JD) | H59: 3000 | I59: 3000 | J59: 3000 | K59: 0 | L59: 0 | M59: 0 | N59: 0 | O59: 0 | P59: 일치 | R59: .png:3000 | S59: .txt:3000 | T59: E:\AI_CCTV_DATASET\original\aihub_data_seg\image\1-6.이음부-단차(Joint-Displaced,JD) | U59: E:\AI_CCTV_DATASET\original\aihub_data_seg\labels\JD
A60: aihub_data_seg | B60: SEG | C60: 전체 | E60: JF | F60: 이음부(손상) | G60: 1-5.이음부-손상(Joint-Faulty,JF) | H60: 2997 | I60: 2997 | J60: 2997 | K60: 0 | L60: 0 | M60: 0 | N60: 0 | O60: 0 | P60: 일치 | R60: .png:2997 | S60: .txt:2997 | T60: E:\AI_CCTV_DATASET\original\aihub_data_seg\image\1-5.이음부-손상(Joint-Faulty,JF) | U60: E:\AI_CCTV_DATASET\original\aihub_data_seg\labels\JF
A61: aihub_data_seg | B61: SEG | C61: 전체 | E61: LP | F61: 연결관(돌출) | G61: 1-4.연결관-돌출(Lateral-Protruding,LP) | H61: 2999 | I61: 2999 | J61: 2999 | K61: 0 | L61: 0 | M61: 0 | N61: 0 | O61: 0 | P61: 일치 | R61: .png:2999 | S61: .txt:2999 | T61: E:\AI_CCTV_DATASET\original\aihub_data_seg\image\1-4.연결관-돌출(Lateral-Protruding,LP) | U61: E:\AI_CCTV_DATASET\original\aihub_data_seg\labels\LP
A62: aihub_data_seg | B62: SEG | C62: 전체 | E62: SD | F62: 표면손상 | G62: 1-2.표면손상(Surface-Damage,SD) | H62: 2998 | I62: 2998 | J62: 2998 | K62: 0 | L62: 0 | M62: 0 | N62: 0 | O62: 0 | P62: 일치 | R62: .png:2998 | S62: .txt:2998 | T62: E:\AI_CCTV_DATASET\original\aihub_data_seg\image\1-2.표면손상(Surface-Damage,SD) | U62: E:\AI_CCTV_DATASET\original\aihub_data_seg\labels\SD
A63: rename_data_s20_s22_seg | B63: SEG | C63: S20 | D63: 2020 | E63: BC | F63: 좌굴 | G63: BC_S20_좌굴 | H63: 105 | I63: 105 | J63: 105 | K63: 0 | L63: 0 | M63: 0 | N63: 0 | O63: 0 | P63: 일치 | R63: .jpg:105 | S63: .json:105 | T63: E:\AI_CCTV_DATASET\original\rename_data_s20_s22_seg\BC_S20_좌굴\images | U63: E:\AI_CCTV_DATASET\original\rename_data_s20_s22_seg\BC_S20_좌굴\labels
A64: rename_data_s20_s22_seg | B64: SEG | C64: S20 | D64: 2020 | E64: BK | F64: 파손 | G64: BK_S20_파손 | H64: 730 | I64: 730 | J64: 730 | K64: 0 | L64: 0 | M64: 0 | N64: 0 | O64: 0 | P64: 일치 | R64: .jpg:584, .png:146 | S64: .xml:600, .json:130 | T64: E:\AI_CCTV_DATASET\original\rename_data_s20_s22_seg\BK_S20_파손\images | U64: E:\AI_CCTV_DATASET\original\rename_data_s20_s22_seg\BK_S20_파손\labels
...

Sheet 폴더 구조
A1: original 폴더 구조
A3: 원본 묶음 | B3: 작업 | C3: 하위 구조 | D3: 이미지 형식 | E3: 라벨 형식 | F3: 기준 경로 / 비고
A4: rename_data_s20_s22_bbox | B4: BBOX | C4: 결함별 폴더 / images, labels | D4: JPG, PNG | E4: XML(2020), JSON(2022) | F4: E:\AI_CCTV_DATASET\original\rename_data_s20_s22_bbox
A5: rename_data_s20_s22_seg | B5: SEG | C5: 결함별 폴더 / images, labels | D5: JPG, PNG | E5: XML·JSON(2020), JSON(2022) | F5: E:\AI_CCTV_DATASET\original\rename_data_s20_s22_seg
A6: aihub_data_bbox | B6: BBOX | C6: image / 코드별 폴더, labels / 코드별 폴더 | D6: PNG | E6: YOLO TXT | F6: E:\AI_CCTV_DATASET\original\aihub_data_bbox ※ Train·Vaild 통합, 중복 라벨 제거 완료
A7: aihub_data_seg | B7: SEG | C7: image / 원본 결함명 폴더, labels / 코드별 폴더 | D7: PNG | E7: YOLO Seg TXT | F7: E:\AI_CCTV_DATASET\original\aihub_data_seg
A9: 구조 예시
A10: original ├─ rename_data_s20_s22_bbox │ └─ [결함 폴더] │ ├─ images │ └─ labels ├─ rename_data_s20_s22_seg │ └─ [결함 폴더] / images, labels ├─ aihub_data_bbox │ ├─ image / [코드] │ └─ labels / [코드] └─ aihub_data_seg ├─ image └─ labels

Sheet 클래스 코드
A1: 하수관로 결함 클래스 코드
A3: 클래스 번호 | B3: 코드 | C3: 분류 | D3: 결함 종류
A4: 0 | B4: CC | C4: 구조결함 | D4: 균열(원주)
A5: 1 | B5: CL | C5: 구조결함 | D5: 균열(길이)
A6: 2 | B6: CM | C6: 구조결함 | D6: 균열(복합)
A7: 3 | B7: SD | C7: 구조결함 | D7: 표면손상
A8: 4 | B8: BC | C8: 구조결함 | D8: 좌굴
A9: 5 | B9: LD | C9: 구조결함 | D9: 라이닝 결함
A10: 6 | B10: DF | C10: 구조결함 | D10: 변형
A11: 7 | B11: BK | C11: 구조결함 | D11: 파손
A12: 8 | B12: CX | C12: 구조결함 | D12: 붕괴
A13: 9 | B13: PO | C13: 구조결함 | D13: 영구장애물
A14: 10 | B14: HL | C14: 구조결함 | D14: 천공
A15: 11 | B15: LP | C15: 구조결함 | D15: 연결관(돌출)
... A34: 30 | B34: OUT_CAR | C34: 정상 | D34: 하수관로 외부(자동차)
